Workbook

Sheet Summary
A1: Hunt results export
A2: Exported 2026-10-27 18:53 UTC from artifacts/hunt/cycle_*/report.json. A snapshot of saved results: re-run `dotnet run --project src/Backtester.Cli -- export` to refresh.
A4: Headline | B4: Value | C4: Notes
A5: Hunt cycles with results | B5: 3 → 12 (10 cycles) | C5: Cycles 1–2 were the data and engine audits (see Cycles).
A6: Hypotheses tested | B6: =COUNTA('Strategies'!$C$2:$C$40) -> 39 | C6: One row each on the Strategies sheet.
A7: Passed every rule | B7: =COUNTIF('Strategies'!$F$2:$F$40,"PASSED") -> 0 | C7: A pass needs every kill rule, a plateau optimum and the single locked out-of-sample run.
A8: Reached the locked OOS run | B8: =COUNT('Strategies'!$AL$2:$AL$40) -> 1 | C8: Out-of-sample window used once per surviving candidate.
A9: Champion | B9: none | C9: From the latest cycle report.
A10: Parameter sets evaluated (cumulative) | B10: 312 | C10: Every optimizer evaluation counts; it deflates the Sharpe bar.
A11: Luck bar (annualized Sharpe) | B11: 1.1230467 | C11: Best Sharpe expected from 312 trials with no real edge (deflated-Sharpe expected maximum).
A12: Best development Sharpe | B12: =MAX('Strategies'!$P$2:$P$40) -> 0.98077415 | C12: On 2021–2023 data; kill bar is 0.50.
A13: achieved by | B13: =INDEX('Strategies'!$C$2:$C$40,MATCH(MAX('Strategies'!$P$2:$P$40),'Strategies'!$P$2:$P$40,0)) -> funding-fade-wide
A14: in cycle | B14: =INDEX('Strategies'!$B$2:$B$40,MATCH(MAX('Strategies'!$P$2:$P$40),'Strategies'!$P$2:$P$40,0)) -> 8
A15: Buy & hold, development window | B15: 0.46168216 | C15: net · Sharpe 0.52 · max DD 77.2% · 2021-01-01 → 2024-01-01
A16: Buy & hold, locked OOS window | B16: 0.89066731 | C16: net · Sharpe 0.71 · max DD 53.8% · 2024-01-01 → 2026-10-26
A18: Top 10 by development Sharpe
A19: Strategy | B19: Family | C19: Cycle | D19: Net % | E19: Profit factor | F19: Sharpe | G19: Max DD % | H19: Trades / yr | I19: Quarters passed (of 4) | J19: OOS net % | K19: Kill reasons
A20: =IF('Strategies'!C2="","",'Strategies'!C2) -> funding-fade-wide | B20: =IF('Strategies'!D2="","",'Strategies'!D2) -> funding-carry | C20: =IF('Strategies'!B2="","",'Strategies'!B2) -> 8 | D20: =IF('Strategies'!M2="","",'Strategies'!M2) -> 0.21307526 | E20: =IF('Strategies'!O2="","",'Strategies'!O2) -> 1.3742214 | F20: =IF('Strategies'!P2="","",'Strategies'!P2) -> 0.98077415 | G20: =IF('Strategies'!S2="","",'Strategies'!S2) -> 0.054972413 | H20: =IF('Strategies'!U2="","",'Strategies'!U2) -> 66.045205 | I20: =IF('Strategies'!AH2="","",'Strategies'!AH2) -> 3 | J20: =IF('Strategies'!AL2="","",'Strategies'!AL2) -> -0.0016814471 | K20: =IF('Strategies'!H2="","",'Strategies'!H2) -> PF 1.00 < 1.10; Sharpe 0.02 < 0.50
A21: =IF('Strategies'!C3="","",'Strategies'!C3) -> crowding-filtered-breakout | B21: =IF('Strategies'!D3="","",'Strategies'!D3) -> funding-filtered-trend | C21: =IF('Strategies'!B3="","",'Strategies'!B3) -> 6 | D21: =IF('Strategies'!M3="","",'Strategies'!M3) -> 0.15923662 | E21: =IF('Strategies'!O3="","",'Strategies'!O3) -> 1.4135226 | F21: =IF('Strategies'!P3="","",'Strategies'!P3) -> 0.84643046 | G21: =IF('Strategies'!S3="","",'Strategies'!S3) -> 0.052157462 | H21: =IF('Strategies'!U3="","",'Strategies'!U3) -> 48.032877 | I21: =IF('Strategies'!AH3="","",'Strategies'!AH3) -> 2 | J21: =IF('Strategies'!AL3="","",'Strategies'!AL3) | K21: =IF('Strategies'!H3="","",'Strategies'!H3) -> 48.0 trades/yr < 50 (144 trades); walk-forward: 2 of 4 folds failed
A22: =IF('Strategies'!C4="","",'Strategies'!C4) -> funding-crowding-fade | B22: =IF('Strategies'!D4="","",'Strategies'!D4) -> funding-carry | C22: =IF('Strategies'!B4="","",'Strategies'!B4) -> 5 | D22: =IF('Strategies'!M4="","",'Strategies'!M4) -> 0.10482396 | E22: =IF('Strategies'!O4="","",'Strategies'!O4) -> 1.2323671 | F22: =IF('Strategies'!P4="","",'Strategies'!P4) -> 0.60577696 | G22: =IF('Strategies'!S4="","",'Strategies'!S4) -> 0.063121796 | H22: =IF('Strategies'!U4="","",'Strategies'!U4) -> 57.706164 | I22: =IF('Strategies'!AH4="","",'Strategies'!AH4) -> 3 | J22: =IF('Strategies'!AL4="","",'Strategies'!AL4) | K22: =IF('Strategies'!H4="","",'Strategies'!H4) -> optimum on the search-range edge of quantile
A23: =IF('Strategies'!C5="","",'Strategies'!C5) -> max-min-daily | B23: =IF('Strategies'!D5="","",'Strategies'!D5) -> daily-extremes | C23: =IF('Strategies'!B5="","",'Strategies'!B5) -> 6 | D23: =IF('Strategies'!M5="","",'Strategies'!M5) -> 0.073254125 | E23: =IF('Strategies'!O5="","",'Strategies'!O5) -> 1.2364224 | F23: =IF('Strategies'!P5="","",'Strategies'!P5) -> 0.60372088 | G23: =IF('Strategies'!S5="","",'Strategies'!S5) -> 0.049334818 | H23: =IF('Strategies'!U5="","",'Strategies'!U5) -> 68.713699 | I23: =IF('Strategies'!AH5="","",'Strategies'!AH5) -> 1 | J23: =IF('Strategies'!AL5="","",'Strategies'!AL5) | K23: =IF('Strategies'!H5="","",'Strategies'!H5) -> walk-forward: 3 of 4 folds failed
A24: =IF('Strategies'!C6="","",'Strategies'!C6) -> cipher-a-ribbon | B24: =IF('Strategies'!D6="","",'Strategies'!D6) -> ema-ribbon | C24: =IF('Strategies'!B6="","",'Strategies'!B6) -> 9 | D24: =IF('Strategies'!M6="","",'Strategies'!M6) -> 0.23724959 | E24: =IF('Strategies'!O6="","",'Strategies'!O6) -> 1.2233115 | F24: =IF('Strategies'!P6="","",'Strategies'!P6) -> 0.56698698 | G24: =IF('Strategies'!S6="","",'Strategies'!S6) -> 0.12315516 | H24: =IF('Strategies'!U6="","",'Strategies'!U6) -> 73.05 | I24: =IF('Strategies'!AH6="","",'Strategies'!AH6) -> 1 | J24: =IF('Strategies'!AL6="","",'Strategies'!AL6) | K24: =IF('Strategies'!H6="","",'Strategies'!H6) -> walk-forward: 3 of 4 folds failed
A25: =IF('Strategies'!C7="","",'Strategies'!C7) -> donchian-ensemble-trend | B25: =IF('Strategies'!D7="","",'Strategies'!D7) -> trend-ensemble | C25: =IF('Strategies'!B7="","",'Strategies'!B7) -> 5 | D25: =IF('Strategies'!M7="","",'Strategies'!M7) -> 0.088912231 | E25: =IF('Strategies'!O7="","",'Strategies'!O7) -> 1.2300481 | F25: =IF('Strategies'!P7="","",'Strategies'!P7) -> 0.48323996 | G25: =IF('Strategies'!S7="","",'Strategies'!S7) -> 0.073950994 | H25: =IF('Strategies'!U7="","",'Strategies'!U7) -> 42.362329 | I25: =IF('Strategies'!AH7="","",'Strategies'!AH7) -> 2 | J25: =IF('Strategies'!AL7="","",'Strategies'!AL7) | K25: =IF('Strategies'!H7="","",'Strategies'!H7) -> Sharpe 0.48 < 0.50; 42.4 trades/yr < 50 (127 trades); walk-forward: 2 of 4 folds failed
A26: =IF('Strategies'!C8="","",'Strategies'!C8) -> supertrend | B26: =IF('Strategies'!D8="","",'Strategies'!D8) -> atr-trend | C26: =IF('Strategies'!B8="","",'Strategies'!B8) -> 10 | D26: =IF('Strategies'!M8="","",'Strategies'!M8) -> 0.28584244 | E26: =IF('Strategies'!O8="","",'Strategies'!O8) -> 1.1402035 | F26: =IF('Strategies'!P8="","",'Strategies'!P8) -> 0.45924006 | G26: =IF('Strategies'!S8="","",'Strategies'!S8) -> 0.35312773 | H26: =IF('Strategies'!U8="","",'Strategies'!U8) -> 109.40822 | I26: =IF('Strategies'!AH8="","",'Strategies'!AH8) -> 1 | J26: =IF('Strategies'!AL8="","",'Strategies'!AL8) | K26: =IF('Strategies'!H8="","",'Strategies'!H8) -> Sharpe 0.46 < 0.50; max DD 35.3% > 30%; walk-forward: 3 of 4 folds failed
A27: =IF('Strategies'!C9="","",'Strategies'!C9) -> impulse-bar-continuation | B27: =IF('Strategies'!D9="","",'Strategies'!D9) -> vol-state | C27: =IF('Strategies'!B9="","",'Strategies'!B9) -> 4 | D27: =IF('Strategies'!M9="","",'Strategies'!M9) -> 0.17560134 | E27: =IF('Strategies'!O9="","",'Strategies'!O9) -> 1.0692856 | F27: =IF('Strategies'!P9="","",'Strategies'!P9) -> 0.43169466 | G27: =IF('Strategies'!S9="","",'Strategies'!S9) -> 0.17319166 | H27: =IF('Strategies'!U9="","",'Strategies'!U9) -> 153.77192 | I27: =IF('Strategies'!AH9="","",'Strategies'!AH9) -> 3 | J27: =IF('Strategies'!AL9="","",'Strategies'!AL9) | K27: =IF('Strategies'!H9="","",'Strategies'!H9) -> PF 1.07 < 1.10; Sharpe 0.43 < 0.50
A28: =IF('Strategies'!C10="","",'Strategies'!C10) -> keltner-breakout | B28: =IF('Strategies'!D10="","",'Strategies'!D10) -> vol-breakout | C28: =IF('Strategies'!B10="","",'Strategies'!B10) -> 3 | D28: =IF('Strategies'!M10="","",'Strategies'!M10) -> 0.20778104 | E28: =IF('Strategies'!O10="","",'Strategies'!O10) -> 1.0777426 | F28: =IF('Strategies'!P10="","",'Strategies'!P10) -> 0.41187191 | G28: =IF('Strategies'!S10="","",'Strategies'!S10) -> 0.25017329 | H28: =IF('Strategies'!U10="","",'Strategies'!U10) -> 166.44726 | I28: =IF('Strategies'!AH10="","",'Strategies'!AH10) -> 2 | J28: =IF('Strategies'!AL10="","",'Strategies'!AL10) | K28: =IF('Strategies'!H10="","",'Strategies'!H10) -> PF 1.08 < 1.10; Sharpe 0.41 < 0.50; walk-forward: 2 of 4 folds failed
A29: =IF('Strategies'!C11="","",'Strategies'!C11) -> funding-tilt | B29: =IF('Strategies'!D11="","",'Strategies'!D11) -> funding-carry | C29: =IF('Strategies'!B11="","",'Strategies'!B11) -> 7 | D29: =IF('Strategies'!M11="","",'Strategies'!M11) -> 0.077378305 | E29: =IF('Strategies'!O11="","",'Strategies'!O11) -> 1.1165657 | F29: =IF('Strategies'!P11="","",'Strategies'!P11) -> 0.37472847 | G29: =IF('Strategies'!S11="","",'Strategies'!S11) -> 0.082201361 | H29: =IF('Strategies'!U11="","",'Strategies'!U11) -> 74.717808 | I29: =IF('Strategies'!AH11="","",'Strategies'!AH11) -> 2 | J29: =IF('Strategies'!AL11="","",'Strategies'!AL11) | K29: =IF('Strategies'!H11="","",'Strategies'!H11) -> Sharpe 0.37 < 0.50; walk-forward: 2 of 4 folds failed
A31: Sheets
A32: Strategies | B32: One row per hypothesis, ranked by development Sharpe: verdict, kill reasons, parameters, every dev metric, the walk-forward quarters, the locked OOS result, rules and artifact folders. Filter and sort freely.
A33: Parameters | B33: Every parameter of every hypothesis: default, optimized value, and its search grid (searched in the cycle, or the registry grid when rejected before optimization).
A34: Quarters | B34: The four walk-forward test quarters per hypothesis, for default and optimized parameters, with train and test windows.
A35: Optimization | B35: Grid search summary for hypotheses that were optimized: grid size, evaluations, edge and plateau checks, best point.
A36: Top trials | B36: The ten best parameter sets and the neighbours of the optimum for each optimized hypothesis.
A37: Slippage | B37: Slippage sensitivity of optimized candidates (0x to 2x the base slippage).
A38: Locked OOS | B38: Development vs locked out-of-sample vs buy & hold for every candidate that reached the OOS run, plus trade distributions.
A39: Cycles | B39: Per cycle: date, hypotheses, trial counts, luck bar, champion, buy & hold, warnings, report and research-notes paths.
A40: Settings | B40: Data, costs, sizing, risk, windows, engine conventions and the hunt rules every cycle used.
A42: How to read
A43: Development metrics use the optimized parameters where optimization ran, otherwise the defaults (column 'Metrics from').
A44: A walk-forward quarter passes only if it makes money and its profit factor is at least the fold minimum; more than one failed quarter kills a hypothesis.
...

Sheet Strategies
A1: Rank (dev Sharpe) | B1: Cycle | C1: Strategy | D1: Family | E1: Strategy version | F1: Verdict | G1: Stopped at | H1: Kill reasons | I1: Metrics from | J1: Parameters used | K1: Default parameters | L1: Optimized parameters | M1: Net % | N1: CAGR % | O1: Profit factor | P1: Sharpe | Q1: Sortino | R1: Calmar | S1: Max DD % | T1: Trades | U1: Trades / yr | V1: Win rate % | W1: Avg trade $ | X1: Time in market % | Y1: Turnover / yr | Z1: Fees $ | AA1: Funding received $ | AB1: Slippage cost $ | AC1: Final equity $ | AD1: 2022Q1 net % | AE1: 2022Q3 net % | AF1: 2023Q1 net % | AG1: 2023Q3 net % | AH1: Quarters passed (of 4) | AI1: Defaults: net % | AJ1: Defaults: PF | AK1: Defaults: Sharpe | AL1: OOS net % | AM1: OOS PF | AN1: OOS Sharpe | AO1: OOS max DD % | AP1: OOS trades | AQ1: OOS win rate % | AR1: Rules | AS1: Dev run folder | AT1: OOS run folder | AU1: Cycle report
A2: 1 | B2: 8 | C2: funding-fade-wide | D2: funding-carry | E2: 1 | F2: REJECTED | G2: locked-oos | H2: PF 1.00 < 1.10; Sharpe 0.02 < 0.50 | I2: optimized | J2: quantile=0.3, holdBars=96, stopMult=1.5 | K2: quantile=0.3, holdBars=96, stopMult=1.5 | L2: quantile=0.3, holdBars=96, stopMult=1.5 | M2: 0.21307526 | N2: 0.066551262 | O2: 1.3742214 | P2: 0.98077415 | Q2: 1.5559831 | R2: 1.2106302 | S2: 0.054972413 | T2: 198 | U2: 66.045205 | V2: 0.53535354 | W2: 10.761377 | X2: 0.65631659 | Y2: 20.380269 | Z2: 274.08689 | AA2: 290.96374 | AB2: 137.04353 | AC2: 12130.753 | AD2: -0.019808585 | AE2: 0.0010741 | AF2: 0.034226995 | AG2: 0.010649348 | AH2: 3 | AI2: 0.21307526 | AJ2: 1.3742214 | AK2: 0.98077415 | AL2: -0.0016814471 | AM2: 0.9973536 | AN2: 0.023264166 | AO2: 0.097838418 | AP2: 195 | AQ2: 0.48717949 | AR2: funding-crowding-fade (rank = 3-day mean funding vs the previous 90 days; short on a close crossing below EMA(24) when rank >= 1 - quantile, long on a cross above when rank <= quantile; exit after holdBars; stop stopMult x dATR) with the quantile range centred on cycle 5's edge optimum. | AS2: artifacts/runs/hunt_cycle_8/funding-fade-wide/optimized_dev | AT2: artifacts/runs/hunt_cycle_8/funding-fade-wide/locked_oos | AU2: artifacts/hunt/cycle_8/report.html
A3: 2 | B3: 6 | C3: crowding-filtered-breakout | D3: funding-filtered-trend | E3: 1 | F3: REJECTED | G3: dev-baseline | H3: 48.0 trades/yr < 50 (144 trades); walk-forward: 2 of 4 folds failed | I3: defaults | J3: channelDays=4, maxRank=0.8, trailMult=2 | K3: channelDays=4, maxRank=0.8, trailMult=2 | M3: 0.15923662 | N3: 0.050522476 | O3: 1.4135226 | P3: 0.84643046 | Q3: 1.530076 | R3: 0.96865288 | S3: 0.052157462 | T3: 144 | U3: 48.032877 | V3: 0.36805556 | W3: 11.058099 | X3: 0.57914764 | Y3: 11.058524 | Z3: 138.85203 | AA3: -97.527766 | AB3: 69.42609 | AC3: 11592.366 | AD3: 0.016088347 | AE3: -0.018534573 | AF3: 0.1386174 | AG3: -0.02744186 | AH3: 2 | AI3: 0.15923662 | AJ3: 1.4135226 | AK3: 0.84643046 | AR3: Long on a close above the high of the previous channelDays x 24 bars only if the 3-day funding rank (as in funding-crowding-fade) is <= maxRank; short below the low only if the rank is >= 1 - maxRank (maxRank 1 = no filter). Exit on the opposite channel of half the length; stop trails the best close by trailMult x dATR. | AS3: artifacts/runs/hunt_cycle_6/crowding-filtered-breakout/baseline_dev | AU3: artifacts/hunt/cycle_6/report.html
A4: 3 | B4: 5 | C4: funding-crowding-fade | D4: funding-carry | E4: 1 | F4: REJECTED | G4: optimization | H4: optimum on the search-range edge of quantile | I4: defaults | J4: quantile=0.2, holdBars=72, stopMult=1.5 | K4: quantile=0.2, holdBars=72, stopMult=1.5 | M4: 0.10482396 | N4: 0.033810436 | O4: 1.2323671 | P4: 0.60577696 | Q4: 0.98307117 | R4: 0.53563805 | S4: 0.063121796 | T4: 173 | U4: 57.706164 | V4: 0.4566474 | W4: 6.0591882 | X4: 0.44493912 | Y4: 18.375137 | Z4: 235.80863 | AA4: 248.85967 | AB4: 117.90436 | AC4: 11048.24 | AD4: 0.033577515 | AE4: -0.009256558 | AF4: 0.055255294 | AG4: 0.021720419 | AH4: 3 | AI4: 0.10482396 | AJ4: 1.2323671 | AK4: 0.60577696 | AR4: Rank = percentile of the mean of the last 9 settled funding rates (3 days) among the previous 270 such means (90 days). Rank >= 1 - quantile (crowded longs): short when the close crosses below EMA(24); rank <= quantile (crowded shorts): long when it crosses above. Exit after holdBars; stop stopMult x dATR. | AS4: artifacts/runs/hunt_cycle_5/funding-crowding-fade/baseline_dev | AU4: artifacts/hunt/cycle_5/report.html
A5: 4 | B5: 6 | C5: max-min-daily | D5: daily-extremes | E5: 1 | F5: REJECTED | G5: dev-baseline | H5: walk-forward: 3 of 4 folds failed | I5: defaults | J5: lookbackDays=10, holdDays=1, stopMult=2 | K5: lookbackDays=10, holdDays=1, stopMult=2 | M5: 0.073254125 | N5: 0.023861467 | O5: 1.2364224 | P5: 0.60372088 | Q5: 0.99741688 | R5: 0.48366382 | S5: 0.049334818 | T5: 206 | U5: 68.713699 | V5: 0.47572816 | W5: 3.5560255 | X5: 0.30677321 | Y5: 15.781076 | Z5: 193.18148 | AA5: -187.51856 | AB5: 96.59079 | AC5: 10732.541 | AD5: -0.011818216 | AE5: -0.0023889132 | AF5: 0.038301239 | AG5: -0.01443785 | AH5: 1 | AI5: 0.073254125 | AJ5: 1.2364224 | AK5: 0.60372088 | AR5: Long only. On a daily close >= the highest close of the previous lookbackDays days (trend) or <= the lowest (reversion), go long; each signal day renews the hold; exit after holdDays day closes without a signal. Stop stopMult x dATR. | AS5: artifacts/runs/hunt_cycle_6/max-min-daily/baseline_dev | AU5: artifacts/hunt/cycle_6/report.html
A6: 5 | B6: 9 | C6: cipher-a-ribbon | D6: ema-ribbon | E6: 1 | F6: REJECTED | G6: dev-baseline | H6: walk-forward: 3 of 4 folds failed | I6: defaults | J6: tfHours=4, atrMult=2.5, diamondExit=1 | K6: tfHours=4, atrMult=2.5, diamondExit=1 | M6: 0.23724959 | N6: 0.073594345 | O6: 1.2233115 | P6: 0.56698698 | Q6: 0.97550549 | R6: 0.59757421 | S6: 0.12315516 | T6: 219 | U6: 73.05 | V6: 0.24657534 | W6: 10.833315 | X6: 0.82541857 | Y6: 39.207036 | Z6: 493.86154 | AA6: -178.58362 | AB6: 246.9309 | AC6: 12372.496 | AD6: -0.0095112162 | AE6: -0.01430066 | AF6: 0.34659736 | AG6: -0.039469763 | AH6: 1 | AI6: 0.23724959 | AJ6: 1.2233115 | AK6: 0.56698698 | AR6: Market Cipher A: EMA(11) crossing above EMA(33) goes long, below goes short; with diamondExit = 1 a long also exits on a 'blood diamond' (bearish WT cross on the period EMA(5) crosses under EMA(11)), a short on the mirror; stop atrMult x ATR(14) of the period bars. | AS6: artifacts/runs/hunt_cycle_9/cipher-a-ribbon/baseline_dev | AU6: artifacts/hunt/cycle_9/report.html
A7: 6 | B7: 5 | C7: donchian-ensemble-trend | D7: trend-ensemble | E7: 1 | F7: REJECTED | G7: dev-baseline | H7: Sharpe 0.48 < 0.50; 42.4 trades/yr < 50 (127 trades); walk-forward: 2 of 4 folds failed | I7: defaults | J7: baseDays=2, minAgree=3, trailMult=2 | K7: baseDays=2, minAgree=3, trailMult=2 | M7: 0.088912231 | N7: 0.028820015 | O7: 1.2300481 | P7: 0.48323996 | Q7: 0.81971115 | R7: 0.38971775 | S7: 0.073950994 | T7: 127 | U7: 42.362329 | V7: 0.32283465 | W7: 7.0009631 | X7: 0.76887367 | Y7: 9.8930684 | Z7: 120.29268 | AA7: -232.8515 | AB7: 60.146391 | AC7: 10889.122 | AD7: 0.0079147686 | AE7: -0.027916379 | AF7: 0.094741871 | AG7: -0.045472115 | AH7: 2 | AI7: 0.088912231 | AJ7: 1.2300481 | AK7: 0.48323996 | AR7: Four Donchian models with lookbacks baseDays x 1, 2, 4, 8 days; each turns long on a close above the high of its previous bars (short below the low) and keeps that state. Long on a fresh breakout of the fastest channel when >= minAgree models are long (short: mirror); exit when long models no longer outnumber short ones; stop trails the best close by trailMult x dATR. | AS7: artifacts/runs/hunt_cycle_5/donchian-ensemble-trend/baseline_dev | AU7: artifacts/hunt/cycle_5/report.html
A8: 7 | B8: 10 | C8: supertrend | D8: atr-trend | E8: 1 | F8: REJECTED | G8: dev-baseline | H8: Sharpe 0.46 < 0.50; max DD 35.3% > 30%; walk-forward: 3 of 4 folds failed | I8: defaults | J8: tfHours=4, atrLen=10, mult=3 | K8: tfHours=4, atrLen=10, mult=3 | M8: 0.28584244 | N8: 0.08747892 | O8: 1.1402035 | P8: 0.45924006 | Q8: 0.76384137 | R8: 0.247726 | S8: 0.35312773 | T8: 328 | U8: 109.40822 | V8: 0.22256098 | W8: 8.7147085 | X8: 0.96038813 | Y8: 120.20376 | Z8: 1841.4178 | AA8: -1662.5258 | AB8: 920.7092 | AC8: 12858.424 | AD8: -0.037250665 | AE8: -0.10110318 | AF8: 0.23331553 | AG8: -0.05535592 | AH8: 1 | AI8: 0.28584244 | AJ8: 1.1402035 | AK8: 0.45924006 | AR8: SuperTrend(atrLen, mult) on tfHours bars: hold its direction and flip with it; the SuperTrend line is the trailing stop; a stop-out is re-entered on the next period close if the direction still holds. | AS8: artifacts/runs/hunt_cycle_10/supertrend/baseline_dev | AU8: artifacts/hunt/cycle_10/report.html
A9: 8 | B9: 4 | C9: impulse-bar-continuation | D9: vol-state | E9: 1 | F9: REJECTED | G9: dev-baseline | H9: PF 1.07 < 1.10; Sharpe 0.43 < 0.50 | I9: defaults | J9: rangeAtr=2.5, bodyFrac=0.6, holdBars=12, atrMult=2 | K9: rangeAtr=2.5, bodyFrac=0.6, holdBars=12, atrMult=2 | M9: 0.17560134 | N9: 0.055446114 | O9: 1.0692856 | P9: 0.43169466 | Q9: 0.75123038 | R9: 0.3201431 | S9: 0.17319166 | T9: 461 | U9: 153.77192 | V9: 0.40563991 | W9: 3.8091397 | X9: 0.1554414 | Y9: 198.66253 | Z9: 2872.3503 | AA9: 73.948745 | AB9: 1436.1754 | AC9: 11756.013 | AD9: 0.0072721173 | AE9: 0.031219038 | AF9: 0.048859369 | AG9: -0.046297247 | AH9: 3 | AI9: 0.17560134 | AJ9: 1.0692856 | AK9: 0.43169466 | AR9: Long when true range >= rangeAtr x previous ATR(14), the bar closes up and its body >= bodyFrac x range (short: the mirror); exit after holdBars bars; stop at signal close -/+ atrMult x ATR. | AS9: artifacts/runs/hunt_cycle_4/impulse-bar-continuation/baseline_dev | AU9: artifacts/hunt/cycle_4/report.html
A10: 9 | B10: 3 | C10: keltner-breakout | D10: vol-breakout | E10: 1 | F10: REJECTED | G10: dev-baseline | H10: PF 1.08 < 1.10; Sharpe 0.41 < 0.50; walk-forward: 2 of 4 folds failed | I10: defaults | J10: emaLen=48, bandMult=2, atrMult=3 | K10: emaLen=48, bandMult=2, atrMult=3 | M10: 0.20778104 | N10: 0.064996354 | O10: 1.0777426 | P10: 0.41187191 | Q10: 0.77871825 | R10: 0.25980533 | S10: 0.25017329 | T10: 499 | U10: 166.44726 | V10: 0.29659319 | W10: 4.1639487 | X10: 0.59828767 | Y10: 147.48674 | Z10: 2002.1861 | AA10: -34.858917 | AB10: 1001.0932 | AC10: 12077.81 | AD10: 0.026238381 | AE10: -0.088284754 | AF10: 0.28077908 | AG10: -0.14399856 | AH10: 2 | AI10: 0.20778104 | AJ10: 1.0777426 | AK10: 0.41187191 | AR10: Long when close > EMA(emaLen) + bandMult x ATR(14), short when close < EMA - bandMult x ATR(14); exit when close crosses back over the EMA; stop at entry-bar close -/+ ATR(14) x atrMult. | AS10: artifacts/runs/hunt_cycle_3/keltner-breakout/baseline_dev | AU10: artifacts/hunt/cycle_3/report.html
A11: 10 | B11: 7 | C11: funding-tilt | D11: funding-carry | E11: 1 | F11: REJECTED | G11: dev-baseline | H11: Sharpe 0.37 < 0.50; walk-forward: 2 of 4 folds failed | I11: defaults | J11: threshold=0.4, holdBars=96, stopMult=1.5 | K11: threshold=0.4, holdBars=96, stopMult=1.5 | M11: 0.077378305 | N11: 0.025172148 | O11: 1.1165657 | P11: 0.37472847 | Q11: 0.57393795 | R11: 0.30622544 | S11: 0.082201361 | T11: 224 | U11: 74.717808 | V11: 0.48214286 | W11: 3.4543886 | X11: 0.74277017 | Y11: 22.650223 | Z11: 285.07149 | AA11: 295.77637 | AB11: 142.53578 | AC11: 10773.783 | AD11: -0.034386683 | AE11: -0.0083046087 | AF11: 0.074422529 | AG11: 0.0072867645 | AH11: 2 | AI11: 0.077378305 | AJ11: 1.1165657 | AK11: 0.37472847 | AR11: funding-crowding-fade with the crowding threshold widened up to the median split: short on a close crossing below EMA(24) when the 3-day funding rank >= 1 - threshold, long on a cross above when <= threshold (0.5 = take every cross, on the side opposite the funding tilt). Exit after holdBars; stop stopMult x dATR. | AS11: artifacts/runs/hunt_cycle_7/funding-tilt/baseline_dev | AU11: artifacts/hunt/cycle_7/report.html
A12: 11 | B12: 3 | C12: donchian-breakout | D12: trend | E12: 1 | F12: REJECTED | G12: dev-baseline | H12: Sharpe 0.36 < 0.50; walk-forward: 3 of 4 folds failed | I12: defaults | J12: entryLen=72, exitLen=24, atrMult=3 | K12: entryLen=72, exitLen=24, atrMult=3 | M12: 0.16640921 | N12: 0.052686153 | O12: 1.1006534 | P12: 0.36398477 | Q12: 0.69040906 | R12: 0.25385953 | S12: 0.20754058 | T12: 272 | U12: 90.728767 | V12: 0.30514706 | W12: 6.1179858 | X12: 0.48314307 | Y12: 75.50196 | Z12: 908.09334 | AA12: -264.12862 | AB12: 454.0468 | AC12: 11664.092 | AD12: -0.014703851 | AE12: -0.05151725 | AF12: 0.3700016 | AG12: -0.12031084 | AH12: 1 | AI12: 0.16640921 | AJ12: 1.1006534 | AK12: 0.36398477 | AR12: Long when close > highest high of the previous entryLen bars, short when close < lowest low of the previous entryLen bars; exit long when close < lowest low of the previous exitLen bars (short: close > highest high of previous exitLen bars); stop at entry-bar close -/+ ATR(14) x atrMult. | AS12: artifacts/runs/hunt_cycle_3/donchian-breakout/baseline_dev | AU12: artifacts/hunt/cycle_3/report.html
A13: 12 | B13: 10 | C13: ichimoku-cloud | D13: cloud-trend | E13: 1 | F13: REJECTED | G13: dev-baseline | H13: Sharpe 0.34 < 0.50; walk-forward: 2 of 4 folds failed | I13: defaults | J13: tfHours=4, periodSet=1, atrMult=2.5 | K13: tfHours=4, periodSet=1, atrMult=2.5 | M13: 0.1018249 | N13: 0.032873517 | O13: 1.1006041 | P13: 0.33755998 | Q13: 0.60235917 | R13: 0.21671377 | S13: 0.15169095 | T13: 282 | U13: 94.064384 | V13: 0.29078014 | W13: 3.610812 | X13: 0.58839422 | Y13: 50.505655 | Z13: 611.14281 | AA13: -287.64205 | AB13: 305.57149 | AC13: 11018.249 | AD13: 0.012477797 | AE13: -0.034443341 | AF13: 0.21618451 | AG13: -0.02897293 | AH13: 2 | AI13: 0.1018249 | AJ13: 1.1006041 | AK13: 0.33755998 | AR13: Ichimoku 9/26/52/26 (periodSet 1) or 20/60/120/30 (periodSet 2): long when the close is above the cloud, tenkan > kijun and the close is above the close displacement-1 periods ago, on the period that first becomes true; exit on a close below kijun; short: the mirror; stop atrMult x ATR. | AS13: artifacts/runs/hunt_cycle_10/ichimoku-cloud/baseline_dev | AU13: artifacts/hunt/cycle_10/report.html
A14: 13 | B14: 7 | C14: funding-carry-tilt | D14: funding-carry | E14: 1 | F14: REJECTED | G14: dev-baseline | H14: Sharpe 0.26 < 0.50; 36.7 trades/yr < 50 (110 trades) | I14: defaults | J14: band=0.3, stopMult=2 | K14: band=0.3, stopMult=2 | M14: 0.029459504 | N14: 0.0097316467 | O14: 1.1098681 | P14: 0.2556412 | Q14: 0.39258466 | R14: 0.20324468 | S14: 0.047881434 | T14: 110 | U14: 36.691781 | V14: 0.43636364 | W14: 2.6781367 | X14: 0.46156773 | Y14: 8.58598 | Z14: 104.33447 | AA14: 191.91709 | AB14: 52.167245 | AC14: 10294.595 | AD14: 0.020084821 | AE14: -0.020074129 | AF14: 0.037030244 | AG14: 0.036739 | AH14: 3 | AI14: 0.029459504 | AJ14: 1.1098681 | AK14: 0.2556412 | AR14: Funding alone, no price timing: on each daily close, short when the 3-day funding rank >= 0.5 + band, long when <= 0.5 - band, else flat; re-evaluated daily. Stop stopMult x dATR. | AS14: artifacts/runs/hunt_cycle_7/funding-carry-tilt/baseline_dev | AU14: artifacts/hunt/cycle_7/report.html
... A40: 39 | B40: 4 | C40: volume-climax-reversal | D40: volume | E40: 1 | F40: REJECTED | G40: dev-baseline | H40: PF 0.68 < 1.10; Sharpe -1.52 < 0.50; max DD 46.9% > 30%; walk-forward: 3 of 4 folds failed | I40: defaults | J40: volMult=2, rangeAtr=1.5, maxHold=12 | K40: volMult=2, rangeAtr=1.5, maxHold=12 | M40: -0.43016479 | N40: -0.17105192 | O40: 0.68390661 | P40: -1.5200466 | Q40: -2.1917706 | R40: -0.36491742 | S40: 0.46874146 | T40: 388 | U40: 129.42192 | V40: 0.38917526 | W40: -11.086722 | X40: 0.12016743 | Y40: 166.56287 | Z40: 1438.4228 | AA40: -47.514744 | AB40: 719.21131 | AC40: 5698.3521 | AD40: -0.1108254 | AE40: -0.0642737 | AF40: -0.062820118 | AG40: 0.038133542 | AH40: 1 | AI40: -0.43016479 | AJ40: 0.68390661 | AK40: -1.5200466 | AR40: Long when volume >= volMult x mean volume of the previous 48 bars, range >= rangeAtr x previous ATR(14), lower wick >= 50% of the range and the low is the lowest of the last 24 bars (short: the mirror with the upper wick and 24-bar high); exit after maxHold bars; stop 0.25 ATR beyond the wick. | AS40: artifacts/runs/hunt_cycle_4/volume-climax-reversal/baseline_dev | AU40: artifacts/hunt/cycle_4/report.html

Sheet Parameters
A1: Cycle | B1: Strategy | C1: Parameter | D1: Default | E1: Optimized | F1: Used for metrics | G1: Grid min | H1: Grid max | I1: Grid step | J1: Grid points | K1: Grid values | L1: Grid source
A2: 3 | B2: donchian-breakout | C2: entryLen | D2: 72 | F2: 72 | G2: 24 | H2: 168 | I2: 24 | J2: 7 | K2: 24, 48, 72, 96, 120, 144, 168 | L2: registry grid (not searched: rejected before optimization)
A3: 3 | B3: donchian-breakout | C3: exitLen | D3: 24 | F3: 24 | G3: 12 | H3: 72 | I3: 12 | J3: 6 | K3: 12, 24, 36, 48, 60, 72 | L3: registry grid (not searched: rejected before optimization)
A4: 3 | B4: donchian-breakout | C4: atrMult | D4: 3 | F4: 3 | G4: 2 | H4: 5 | I4: 1 | J4: 4 | K4: 2, 3, 4, 5 | L4: registry grid (not searched: rejected before optimization)
A5: 3 | B5: bollinger-reversion | C5: bbLen | D5: 40 | F5: 40 | G5: 20 | H5: 80 | I5: 10 | J5: 7 | K5: 20, 30, 40, 50, 60, 70, 80 | L5: registry grid (not searched: rejected before optimization)
A6: 3 | B6: bollinger-reversion | C6: bbMult | D6: 2 | F6: 2 | G6: 1.5 | H6: 3 | I6: 0.5 | J6: 4 | K6: 1.5, 2, 2.5, 3 | L6: registry grid (not searched: rejected before optimization)
A7: 3 | B7: bollinger-reversion | C7: atrMult | D7: 3 | F7: 3 | G7: 2 | H7: 5 | I7: 1 | J7: 4 | K7: 2, 3, 4, 5 | L7: registry grid (not searched: rejected before optimization)
A8: 3 | B8: keltner-breakout | C8: emaLen | D8: 48 | F8: 48 | G8: 24 | H8: 120 | I8: 24 | J8: 5 | K8: 24, 48, 72, 96, 120 | L8: registry grid (not searched: rejected before optimization)
A9: 3 | B9: keltner-breakout | C9: bandMult | D9: 2 | F9: 2 | G9: 1 | H9: 3 | I9: 0.5 | J9: 5 | K9: 1, 1.5, 2, 2.5, 3 | L9: registry grid (not searched: rejected before optimization)
A10: 3 | B10: keltner-breakout | C10: atrMult | D10: 3 | F10: 3 | G10: 2 | H10: 5 | I10: 1 | J10: 4 | K10: 2, 3, 4, 5 | L10: registry grid (not searched: rejected before optimization)
A11: 3 | B11: ts-momentum | C11: lookback | D11: 96 | F11: 96 | G11: 24 | H11: 216 | I11: 24 | J11: 9 | K11: 24, 48, 72, 96, 120, 144, 168, 192, 216 | L11: registry grid (not searched: rejected before optimization)
A12: 3 | B12: ts-momentum | C12: threshold | D12: 0.01 | F12: 0.01 | G12: 0 | H12: 0.02 | I12: 0.005 | J12: 5 | K12: 0, 0.005, 0.01, 0.015, 0.02 | L12: registry grid (not searched: rejected before optimization)
A13: 3 | B13: ts-momentum | C13: atrMult | D13: 3 | F13: 3 | G13: 2 | H13: 5 | I13: 1 | J13: 4 | K13: 2, 3, 4, 5 | L13: registry grid (not searched: rejected before optimization)
... A72: 7 | B72: funding-carry-tilt | C72: stopMult | D72: 2 | F72: 2 | G72: 1 | H72: 3 | I72: 0.5 | J72: 5 | K72: 1, 1.5, 2, 2.5, 3 | L72: registry grid (not searched: rejected before optimization)
A73: 8 | B73: funding-fade-wide | C73: quantile | D73: 0.3 | E73: 0.3 | F73: 0.3 | G73: 0.2 | H73: 0.4 | I73: 0.05 | J73: 5 | K73: 0.2, 0.25, 0.3, 0.35, 0.4 | L73: searched in this cycle
A74: 8 | B74: funding-fade-wide | C74: holdBars | D74: 96 | E74: 96 | F74: 96 | G74: 48 | H74: 144 | I74: 24 | J74: 5 | K74: 48, 72, 96, 120, 144 | L74: searched in this cycle
A75: 8 | B75: funding-fade-wide | C75: stopMult | D75: 1.5 | E75: 1.5 | F75: 1.5 | G75: 1 | H75: 2.5 | I75: 0.5 | J75: 4 | K75: 1, 1.5, 2, 2.5 | L75: searched in this cycle
A76: 9 | B76: cipher-b-dots | C76: tfHours | D76: 4 | F76: 4 | G76: 2 | H76: 8 | I76: 2 | J76: 4 | K76: 2, 4, 6, 8 | L76: registry grid (not searched: rejected before optimization)
A77: 9 | B77: cipher-b-dots | C77: level | D77: 53 | F77: 53 | G77: 41 | H77: 65 | I77: 6 | J77: 5 | K77: 41, 47, 53, 59, 65 | L77: registry grid (not searched: rejected before optimization)
A78: 9 | B78: cipher-b-dots | C78: atrMult | D78: 2.5 | F78: 2.5 | G78: 1.5 | H78: 3.5 | I78: 0.5 | J78: 5 | K78: 1.5, 2, 2.5, 3, 3.5 | L78: registry grid (not searched: rejected before optimization)
A79: 9 | B79: cipher-b-sommi-flag | C79: tfHours | D79: 2 | F79: 2 | G79: 2 | H79: 8 | I79: 2 | J79: 4 | K79: 2, 4, 6, 8 | L79: registry grid (not searched: rejected before optimization)
A80: 9 | B80: cipher-b-sommi-flag | C80: htfHours | D80: 12 | F80: 12 | G80: 12 | H80: 24 | I80: 12 | J80: 2 | K80: 12, 24 | L80: registry grid (not searched: rejected before optimization)
A81: 9 | B81: cipher-b-sommi-flag | C81: atrMult | D81: 2.5 | F81: 2.5 | G81: 1.5 | H81: 3.5 | I81: 0.5 | J81: 5 | K81: 1.5, 2, 2.5, 3, 3.5 | L81: registry grid (not searched: rejected before optimization)
A82: 9 | B82: cipher-b-divergence | C82: tfHours | D82: 2 | F82: 2 | G82: 2 | H82: 8 | I82: 2 | J82: 4 | K82: 2, 4, 6, 8 | L82: registry grid (not searched: rejected before optimization)
A83: 9 | B83: cipher-b-divergence | C83: limitScale | D83: 1 | F83: 1 | G83: 0.5 | H83: 1.25 | I83: 0.25 | J83: 4 | K83: 0.5, 0.75, 1, 1.25 | L83: registry grid (not searched: rejected before optimization)
A84: 9 | B84: cipher-b-divergence | C84: atrMult | D84: 2 | F84: 2 | G84: 1 | H84: 3 | I84: 0.5 | J84: 5 | K84: 1, 1.5, 2, 2.5, 3 | L84: registry grid (not searched: rejected before optimization)
A85: 9 | B85: cipher-a-ribbon | C85: tfHours | D85: 4 | F85: 4 | G85: 2 | H85: 8 | I85: 2 | J85: 4 | K85: 2, 4, 6, 8 | L85: registry grid (not searched: rejected before optimization)
A86: 9 | B86: cipher-a-ribbon | C86: atrMult | D86: 2.5 | F86: 2.5 | G86: 1.5 | H86: 3.5 | I86: 0.5 | J86: 5 | K86: 1.5, 2, 2.5, 3, 3.5 | L86: registry grid (not searched: rejected before optimization)
A87: 9 | B87: cipher-a-ribbon | C87: diamondExit | D87: 1 | F87: 1 | G87: 0 | H87: 1 | I87: 1 | J87: 2 | K87: 0, 1 | L87: registry grid (not searched: rejected before optimization)
... A110: 11 | B110: dca-rsi-long | C110: takeProfit | D110: 0.01 | F110: 0.01 | G110: 0.005 | H110: 0.02 | I110: 0.005 | J110: 4 | K110: 0.005, 0.01, 0.015, 0.02 | L110: registry grid (not searched: rejected before optimization)
A111: 11 | B111: dca-rsi-long | C111: orders | D111: 5 | F111: 5 | L111: fixed (not tuned)
A112: 11 | B112: dca-rsi-long | C112: martingale | D112: 0.15 | F112: 0.15 | L112: fixed (not tuned)
A113: 11 | B113: dca-trend-long | C113: maDays | D113: 200 | F113: 200 | G113: 50 | H113: 200 | I113: 50 | J113: 4 | K113: 50, 100, 150, 200 | L113: registry grid (not searched: rejected before optimization)
A114: 11 | B114: dca-trend-long | C114: overlap | D114: 0.1 | F114: 0.1 | G114: 0.05 | H114: 0.2 | I114: 0.05 | J114: 4 | K114: 0.05, 0.1, 0.15, 0.2 | L114: registry grid (not searched: rejected before optimization)
A115: 11 | B115: dca-trend-long | C115: takeProfit | D115: 0.01 | F115: 0.01 | G115: 0.005 | H115: 0.02 | I115: 0.005 | J115: 4 | K115: 0.005, 0.01, 0.015, 0.02 | L115: registry grid (not searched: rejected before optimization)
A116: 11 | B116: dca-trend-long | C116: orders | D116: 5 | F116: 5 | L116: fixed (not tuned)
A117: 11 | B117: dca-trend-long | C117: martingale | D117: 0.15 | F117: 0.15 | L117: fixed (not tuned)
A118: 12 | B118: cascade-fade | C118: dropAtr | D118: 1.5 | F118: 1.5 | G118: 1 | H118: 3 | I118: 0.5 | J118: 5 | K118: 1, 1.5, 2, 2.5, 3 | L118: registry grid (not searched: rejected before optimization)
A119: 12 | B119: cascade-fade | C119: volMult | D119: 1.5 | F119: 1.5 | G119: 1 | H119: 3 | I119: 0.5 | J119: 5 | K119: 1, 1.5, 2, 2.5, 3 | L119: registry grid (not searched: rejected before optimization)
A120: 12 | B120: cascade-fade | C120: holdBars | D120: 24 | F120: 24 | G120: 12 | H120: 48 | I120: 12 | J120: 4 | K120: 12, 24, 36, 48 | L120: registry grid (not searched: rejected before optimization)
...

Sheet Quarters
A1: Cycle | B1: Strategy | C1: Parameters | D1: Fold | E1: Train from | F1: Train to (excl.) | G1: Test from | H1: Test to (excl.) | I1: Net % | J1: Profit factor | K1: Sharpe | L1: Max DD % | M1: Trades | N1: Passed
A2: 3 | B2: donchian-breakout | C2: defaults | D2: 1 | E2: 2021-01-01 | F2: 2022-01-01 | G2: 2022-01-01 | H2: 2022-04-01 | I2: -0.014703851 | J2: 0.90695668 | K2: -0.32014623 | L2: 0.085428179 | M2: 25 | N2: no
A3: 3 | B3: donchian-breakout | C3: defaults | D3: 2 | E3: 2021-07-01 | F3: 2022-07-01 | G3: 2022-07-01 | H3: 2022-10-01 | I3: -0.05151725 | J3: 0.63570528 | K3: -1.4432085 | L3: 0.08556426 | M3: 25 | N3: no
A4: 3 | B4: donchian-breakout | C4: defaults | D4: 3 | E4: 2022-01-01 | F4: 2023-01-01 | G4: 2023-01-01 | H4: 2023-04-01 | I4: 0.3700016 | J4: 4.229092 | K4: 4.3981467 | L4: 0.084826551 | M4: 16 | N4: yes
A5: 3 | B5: donchian-breakout | C5: defaults | D5: 4 | E5: 2022-07-01 | F5: 2023-07-01 | G5: 2023-07-01 | H5: 2023-10-01 | I5: -0.12031084 | J5: 0.36520239 | K5: -3.0320391 | L5: 0.12677103 | M5: 25 | N5: no
A6: 3 | B6: bollinger-reversion | C6: defaults | D6: 1 | E6: 2021-01-01 | F6: 2022-01-01 | G6: 2022-01-01 | H6: 2022-04-01 | I6: -0.042102018 | J6: 0.83562061 | K6: -1.1696669 | L6: 0.065727994 | M6: 60 | N6: no
A7: 3 | B7: bollinger-reversion | C7: defaults | D7: 2 | E7: 2021-07-01 | F7: 2022-07-01 | G7: 2022-07-01 | H7: 2022-10-01 | I7: 0.10407294 | J7: 1.4972525 | K7: 2.9649238 | L7: 0.062929132 | M7: 59 | N7: yes
A8: 3 | B8: bollinger-reversion | C8: defaults | D8: 3 | E8: 2022-01-01 | F8: 2023-01-01 | G8: 2023-01-01 | H8: 2023-04-01 | I8: 0.0045505019 | J8: 1.0212667 | K8: 0.20685208 | L8: 0.063044672 | M8: 60 | N8: yes
A9: 3 | B9: bollinger-reversion | C9: defaults | D9: 4 | E9: 2022-07-01 | F9: 2023-07-01 | G9: 2023-07-01 | H9: 2023-10-01 | I9: -0.012683947 | J9: 0.94680959 | K9: -0.35479343 | L9: 0.082360772 | M9: 66 | N9: no
A10: 3 | B10: keltner-breakout | C10: defaults | D10: 1 | E10: 2021-01-01 | F10: 2022-01-01 | G10: 2022-01-01 | H10: 2022-04-01 | I10: 0.026238381 | J10: 1.1364853 | K10: 0.67224242 | L10: 0.056700441 | M10: 44 | N10: yes
A11: 3 | B11: keltner-breakout | C11: defaults | D11: 2 | E11: 2021-07-01 | F11: 2022-07-01 | G11: 2022-07-01 | H11: 2022-10-01 | I11: -0.088284754 | J11: 0.60896344 | K11: -2.215081 | L11: 0.12067611 | M11: 42 | N11: no
A12: 3 | B12: keltner-breakout | C12: defaults | D12: 3 | E12: 2022-01-01 | F12: 2023-01-01 | G12: 2023-01-01 | H12: 2023-04-01 | I12: 0.28077908 | J12: 2.2761797 | K12: 3.5578257 | L12: 0.083481812 | M12: 33 | N12: yes
A13: 3 | B13: keltner-breakout | C13: defaults | D13: 4 | E13: 2022-07-01 | F13: 2023-07-01 | G13: 2023-07-01 | H13: 2023-10-01 | I13: -0.14399856 | J13: 0.41136441 | K13: -2.9991326 | L13: 0.15114121 | M13: 42 | N13: no
... A143: 11 | B143: dca-rsi-long | C143: defaults | D143: 2 | E143: 2021-07-01 | F143: 2022-07-01 | G143: 2022-07-01 | H143: 2022-10-01 | I143: -0.017811839 | J143: 0.12593026 | K143: -3.097244 | L143: 0.019822046 | M143: 14 | N143: no
A144: 11 | B144: dca-rsi-long | C144: defaults | D144: 3 | E144: 2022-01-01 | F144: 2023-01-01 | G144: 2023-01-01 | H144: 2023-04-01 | I144: 0.0025416016 | J144: ∞ | K144: 2.3121271 | L144: 0.0035343356 | M144: 13 | N144: yes
A145: 11 | B145: dca-rsi-long | C145: defaults | D145: 4 | E145: 2022-07-01 | F145: 2023-07-01 | G145: 2023-07-01 | H145: 2023-10-01 | I145: -0.0078911979 | J145: 0.22124114 | K145: -1.5573056 | L145: 0.010816842 | M145: 13 | N145: no
A146: 11 | B146: dca-trend-long | C146: defaults | D146: 1 | E146: 2021-01-01 | F146: 2022-01-01 | G146: 2022-01-01 | H146: 2022-04-01 | I146: 0 | K146: 0 | L146: 0 | M146: 0 | N146: no
A147: 11 | B147: dca-trend-long | C147: defaults | D147: 2 | E147: 2021-07-01 | F147: 2022-07-01 | G147: 2022-07-01 | H147: 2022-10-01 | I147: 0 | K147: 0 | L147: 0 | M147: 0 | N147: no
A148: 11 | B148: dca-trend-long | C148: defaults | D148: 3 | E148: 2022-01-01 | F148: 2023-01-01 | G148: 2023-01-01 | H148: 2023-04-01 | I148: 0.0097965212 | J148: 1.9436705 | K148: 1.9039994 | L148: 0.010696864 | M148: 106 | N148: yes
A149: 11 | B149: dca-trend-long | C149: defaults | D149: 4 | E149: 2022-07-01 | F149: 2023-07-01 | G149: 2023-07-01 | H149: 2023-10-01 | I149: -0.0082357361 | J149: 0.2255355 | K149: -2.2395281 | L149: 0.011311171 | M149: 12 | N149: no
A150: 12 | B150: cascade-fade | C150: defaults | D150: 1 | E150: 2021-01-01 | F150: 2022-01-01 | G150: 2022-01-01 | H150: 2022-04-01 | I150: -0.15649523 | J150: 0.36036498 | K150: -4.8997901 | L150: 0.15949703 | M150: 37 | N150: no
A151: 12 | B151: cascade-fade | C151: defaults | D151: 2 | E151: 2021-07-01 | F151: 2022-07-01 | G151: 2022-07-01 | H151: 2022-10-01 | I151: -0.0054448191 | J151: 0.97062742 | K151: -0.049839771 | L151: 0.056699944 | M151: 29 | N151: no
A152: 12 | B152: cascade-fade | C152: defaults | D152: 3 | E152: 2022-01-01 | F152: 2023-01-01 | G152: 2023-01-01 | H152: 2023-04-01 | I152: -0.14336427 | J152: 0.41010724 | K152: -4.6702528 | L152: 0.16595259 | M152: 40 | N152: no
A153: 12 | B153: cascade-fade | C153: defaults | D153: 4 | E153: 2022-07-01 | F153: 2023-07-01 | G153: 2023-07-01 | H153: 2023-10-01 | I153: -0.013269974 | J153: 0.90403546 | K153: -0.57536852 | L153: 0.052152114 | M153: 36 | N153: no
A154: 12 | B154: turmoil-reversal | C154: defaults | D154: 1 | E154: 2021-01-01 | F154: 2022-01-01 | G154: 2022-01-01 | H154: 2022-04-01 | I154: 0.062513819 | J154: 4.7583097 | K154: 2.9360187 | L154: 0.011296328 | M154: 8 | N154: yes
A155: 12 | B155: turmoil-reversal | C155: defaults | D155: 2 | E155: 2021-07-01 | F155: 2022-07-01 | G155: 2022-07-01 | H155: 2022-10-01 | I155: 0.0054794207 | J155: 1.3714215 | K155: 0.72730398 | L155: 0.024019177 | M155: 6 | N155: yes
A156: 12 | B156: turmoil-reversal | C156: defaults | D156: 3 | E156: 2022-01-01 | F156: 2023-01-01 | G156: 2023-01-01 | H156: 2023-04-01 | I156: -0.032545021 | J156: 0.71010561 | K156: -1.3290189 | L156: 0.064663028 | M156: 24 | N156: no
A157: 12 | B157: turmoil-reversal | C157: defaults | D157: 4 | E157: 2022-07-01 | F157: 2023-07-01 | G157: 2023-07-01 | H157: 2023-10-01 | I157: 0.0030970364 | J157: ∞ | K157: 2.3575102 | L157: 0.0050389285 | M157: 1 | N157: yes
A158: 12 | B158: round-number-bounce | C158: defaults | D158: 1 | E158: 2021-01-01 | F158: 2022-01-01 | G158: 2022-01-01 | H158: 2022-04-01 | I158: -0.1108181 | J158: 0.60075174 | K158: -2.6715925 | L158: 0.1384382 | M158: 40 | N158: no
A159: 12 | B159: round-number-bounce | C159: defaults | D159: 2 | E159: 2021-07-01 | F159: 2022-07-01 | G159: 2022-07-01 | H159: 2022-10-01 | I159: -0.071258351 | J159: 0.5405401 | K159: -2.055803 | L159: 0.099783019 | M159: 21 | N159: no
A160: 12 | B160: round-number-bounce | C160: defaults | D160: 3 | E160: 2022-01-01 | F160: 2023-01-01 | G160: 2023-01-01 | H160: 2023-04-01 | I160: -0.10953666 | J160: 0.3863405 | K160: -4.0547134 | L160: 0.13359188 | M160: 26 | N160: no
A161: 12 | B161: round-number-bounce | C161: defaults | D161: 4 | E161: 2022-07-01 | F161: 2023-07-01 | G161: 2023-07-01 | H161: 2023-10-01 | I161: 0.024563696 | J161: 1.3317964 | K161: 1.0304873 | L161: 0.031767604 | M161: 19 | N161: yes

Sheet Optimization
A1: Cycle | B1: Strategy | C1: Objective | D1: Grid points | E1: Evaluated | F1: Sampled | G1: Enough trades | H1: Best at edge of | I1: Plateau passed | J1: Optimizer verdict | K1: Best parameters | L1: Best Sharpe | M1: Best PF | N1: Best trades | O1: Best daily Sharpe | P1: Stopped at | Q1: Kill reasons
A2: 5 | B2: funding-crowding-fade | C2: sharpe | D2: 150 | E2: 150 | F2: no | G2: 104 | H2: quantile | I2: yes | J2: best point is on the edge of: quantile | K2: quantile=0.3, holdBars=96, stopMult=1.5 | L2: 0.98077415 | M2: 1.3742214 | N2: 198 | O2: 0.051336065 | P2: optimization | Q2: optimum on the search-range edge of quantile
A3: 8 | B3: funding-fade-wide | C3: sharpe | D3: 100 | E3: 100 | F3: no | G3: 87 | I3: yes | K3: quantile=0.3, holdBars=96, stopMult=1.5 | L3: 0.98077415 | M3: 1.3742214 | N3: 198 | O3: 0.051336065 | P3: locked-oos | Q3: PF 1.00 < 1.10; Sharpe 0.02 < 0.50

Sheet Top trials
A1: Cycle | B1: Strategy | C1: Set | D1: # | E1: Parameters | F1: Sharpe | G1: Profit factor | H1: Trades | I1: Daily Sharpe
A2: 5 | B2: funding-crowding-fade | C2: top 10 | D2: 1 | E2: quantile=0.3, holdBars=96, stopMult=1.5 | F2: 0.98077415 | G2: 1.3742214 | H2: 198 | I2: 0.051336065
A3: 5 | B3: funding-crowding-fade | C3: top 10 | D3: 2 | E3: quantile=0.3, holdBars=120, stopMult=1.5 | F3: 0.93497333 | G3: 1.3736596 | H3: 174 | I3: 0.048938741
A4: 5 | B4: funding-crowding-fade | C4: top 10 | D4: 3 | E4: quantile=0.25, holdBars=96, stopMult=1.5 | F4: 0.8516028 | G4: 1.3368228 | H4: 177 | I4: 0.044574928
A5: 5 | B5: funding-crowding-fade | C5: top 10 | D5: 4 | E5: quantile=0.3, holdBars=120, stopMult=2.5 | F5: 0.7621299 | G5: 1.3075585 | H5: 164 | I5: 0.039891702
A6: 5 | B6: funding-crowding-fade | C6: top 10 | D6: 5 | E6: quantile=0.3, holdBars=120, stopMult=2 | F6: 0.73979249 | G6: 1.2935734 | H6: 168 | I6: 0.038722509
A7: 5 | B7: funding-crowding-fade | C7: top 10 | D7: 6 | E7: quantile=0.3, holdBars=96, stopMult=2 | F7: 0.68285184 | G7: 1.244898 | H7: 194 | I7: 0.035742099
A8: 5 | B8: funding-crowding-fade | C8: top 10 | D8: 7 | E8: quantile=0.3, holdBars=96, stopMult=1 | F8: 0.67212391 | G8: 1.2048646 | H8: 218 | I8: 0.035180573
A9: 5 | B9: funding-crowding-fade | C9: top 10 | D9: 8 | E9: quantile=0.3, holdBars=120, stopMult=3 | F9: 0.64781797 | G9: 1.263823 | H9: 162 | I9: 0.033908342
A10: 5 | B10: funding-crowding-fade | C10: top 10 | D10: 9 | E10: quantile=0.2, holdBars=72, stopMult=1.5 | F10: 0.60577696 | G10: 1.2323671 | H10: 173 | I10: 0.031707815
A11: 5 | B11: funding-crowding-fade | C11: top 10 | D11: 10 | E11: quantile=0.2, holdBars=24, stopMult=3 | F11: 0.55633848 | G11: 1.1687249 | H11: 315 | I11: 0.029120087
A12: 5 | B12: funding-crowding-fade | C12: neighbour | D12: 1 | E12: quantile=0.25, holdBars=96, stopMult=1.5 | F12: 0.8516028 | G12: 1.3368228 | H12: 177 | I12: 0.044574928
A13: 5 | B13: funding-crowding-fade | C13: neighbour | D13: 2 | E13: quantile=0.3, holdBars=72, stopMult=1.5 | F13: 0.48609851 | G13: 1.1517903 | H13: 247 | I13: 0.025443559
... A32: 8 | B32: funding-fade-wide | C32: neighbour | D32: 6 | E32: quantile=0.3, holdBars=96, stopMult=2 | F32: 0.68285184 | G32: 1.244898 | H32: 194 | I32: 0.035742099

Sheet Slippage
A1: Cycle | B1: Strategy | C1: x base slippage | D1: Slippage / side % | E1: Net % | F1: CAGR % | G1: Max DD % | H1: Profit factor | I1: Sharpe
A2: 8 | B2: funding-fade-wide | C2: 0 | D2: 0 | E2: 0.22869554 | F2: 0.071112733 | G2: 0.054314252 | H2: 1.4029146 | I2: 1.0405768
A3: 8 | B3: funding-fade-wide | C3: 0.5 | D3: 0.0001 | E3: 0.22084653 | F3: 0.068825507 | G3: 0.054643797 | H3: 1.3884718 | I3: 1.0106713
A4: 8 | B4: funding-fade-wide | C4: 1 | D4: 0.0002 | E4: 0.21307526 | F4: 0.066551262 | G4: 0.054972413 | H4: 1.3742214 | I4: 0.98077415
A5: 8 | B5: funding-fade-wide | C5: 1.5 | D5: 0.0003 | E5: 0.20538072 | F5: 0.064289886 | G5: 0.055300103 | H5: 1.3601571 | I5: 0.95088598
A6: 8 | B6: funding-fade-wide | C6: 2 | D6: 0.0004 | E6: 0.19776192 | F6: 0.06204127 | G6: 0.055626872 | H6: 1.3462735 | I6: 0.9210076

Sheet Locked OOS
A1: Cycle | B1: Strategy | C1: Section | D1: Metric | E1: Development | F1: Locked OOS | G1: Buy & hold (OOS)
A2: 8 | B2: funding-fade-wide | C2: Run | D2: Parameters | E2: quantile=0.3, holdBars=96, stopMult=1.5 | F2: quantile=0.3, holdBars=96, stopMult=1.5
A3: 8 | B3: funding-fade-wide | C3: Run | D3: Window | E3: 2021-01-01 → 2024-01-01 | F3: 2024-01-01 → 2026-10-26 | G3: 2024-01-01 → 2026-10-26
A4: 8 | B4: funding-fade-wide | C4: Run | D4: Outcome | E4: REJECTED | F4: PF 1.00 < 1.10; Sharpe 0.02 < 0.50
A5: 8 | B5: funding-fade-wide | C5: Performance | D5: Net % | E5: 0.21307526 | F5: -0.0016814471 | G5: 0.89066731
A6: 8 | B6: funding-fade-wide | C6: Performance | D6: CAGR % | E6: 0.066551262 | F6: -0.00059716414 | G6: 0.25367876
A7: 8 | B7: funding-fade-wide | C7: Performance | D7: Profit factor | E7: 1.3742214 | F7: 0.9973536 | G7: ∞
A8: 8 | B8: funding-fade-wide | C8: Performance | D8: Sharpe | E8: 0.98077415 | F8: 0.023264166 | G8: 0.71473167
A9: 8 | B9: funding-fade-wide | C9: Performance | D9: Sortino | E9: 1.5559831 | F9: 0.0330345 | G9: 1.0817313
A10: 8 | B10: funding-fade-wide | C10: Performance | D10: Max DD % | E10: 0.054972413 | F10: 0.097838418 | G10: 0.53755359
A11: 8 | B11: funding-fade-wide | C11: Performance | D11: Trades | E11: 198 | F11: 195 | G11: 1
A12: 8 | B12: funding-fade-wide | C12: Performance | D12: Trades / yr | E12: 66.045205 | F12: 69.216472 | G12: 0.35495627
A13: 8 | B13: funding-fade-wide | C13: Performance | D13: Win rate % | E13: 0.53535354 | F13: 0.48717949 | G13: 1
A14: 8 | B14: funding-fade-wide | C14: Performance | D14: Avg trade $ | E14: 10.761377 | F14: -0.086228055 | G14: 8906.6731
A15: 8 | B15: funding-fade-wide | C15: Performance | D15: Time in market % | E15: 0.65631659 | F15: 0.66784095 | G15: 1
A16: 8 | B16: funding-fade-wide | C16: Performance | D16: Fees $ | E16: 274.08689 | F16: 303.48757 | G16: 11.564096
A17: 8 | B17: funding-fade-wide | C17: Performance | D17: Funding received $ | E17: 290.96374 | F17: 83.514319 | G17: 0
A18: 8 | B18: funding-fade-wide | C18: Performance | D18: Final equity $ | E18: 12130.753 | F18: 9983.1855 | G18: 18906.673
A19: 8 | B19: funding-fade-wide | C19: Trade distribution | D19: Trades | E19: 198 | F19: 195
A20: 8 | B20: funding-fade-wide | C20: Trade distribution | D20: Mean trade % | E20: 0.0057161027 | F20: -0.00026076954
A21: 8 | B21: funding-fade-wide | C21: Trade distribution | D21: Median trade % | E21: 0.0021220518 | F21: -0.0022433113
A22: 8 | B22: funding-fade-wide | C22: Trade distribution | D22: 5th percentile % | E22: -0.0856087 | F22: -0.063270023
A23: 8 | B23: funding-fade-wide | C23: Trade distribution | D23: 25th percentile % | E23: -0.027274454 | F23: -0.036275664
A24: 8 | B24: funding-fade-wide | C24: Trade distribution | D24: 75th percentile % | E24: 0.035608748 | F24: 0.026895749
A25: 8 | B25: funding-fade-wide | C25: Trade distribution | D25: 95th percentile % | E25: 0.11327431 | F25: 0.070984352
A26: 8 | B26: funding-fade-wide | C26: Trade distribution | D26: Worst trade % | E26: -0.18325498 | F26: -0.079042907
A27: 8 | B27: funding-fade-wide | C27: Trade distribution | D27: Best trade % | E27: 0.22324872 | F27: 0.11895816
A28: 8 | B28: funding-fade-wide | C28: Trade distribution | D28: Avg bars held | E28: 88.111111 | F28: 85.579487
A29: 8 | B29: funding-fade-wide | C29: Trade distribution | D29: Win rate % | E29: 0.53535354 | F29: 0.48717949

Sheet Cycles
A1: Cycle | B1: Run (UTC) | C1: Kind | D1: Step / result | E1: Hypotheses | F1: Strategies | G1: Trials before | H1: Trials this cycle | I1: Cumulative trials | J1: Daily Sharpe variance | K1: Luck bar (ann. Sharpe) | L1: Reached OOS | M1: Champion | N1: B&H dev net % | O1: B&H dev Sharpe | P1: B&H dev max DD % | Q1: Report | R1: Research notes | S1: Warnings
A2: 1 | B2: 2026-10-26 14:20:15 | C2: audit | D2: STEP 0 - capability & data audit: AUDIT FAILED
A3: 2 | B3: 2026-10-26 15:01:00 | C3: audit | D3: STEP 0 - capability & data audit (re-run against the local engine): AUDIT PASSED
A4: 3 | B4: 2026-10-26 15:34:19 | C4: hunt | D4: 5 hypotheses, 0 passed | E4: 5 | F4: donchian-breakout, bollinger-reversion, keltner-breakout, ts-momentum, trend-pullback-rsi | G4: 25 | H4: 5 | I4: 30 | J4: 0.00050543399 | K4: 0.89055374 | L4: 0 | M4: none | N4: 0.46168216 | O4: 0.5192431 | P4: 0.77233836 | Q4: artifacts/hunt/cycle_3/report.html | S4: 30 parameter sets have been evaluated on development data so far; the best of that many lucky trials would show a daily Sharpe near 0.0466 (annualized 0.89) with no real edge.; Walk-forward folds use fixed parameters (no per-fold re-optimization, to stay within the optimizer cap); for optimized candidates the test folds lie inside the window the parameters were tuned on, so only the locked OOS run is truly out of sample.; Max drawdown is measured on hourly bar-close equity; intrabar drawdowns are deeper.
A5: 4 | B5: 2026-10-26 19:23:54 | C5: hunt | D5: 5 hypotheses, 0 passed | E5: 5 | F5: failed-breakout-fade, volume-climax-reversal, session-momentum, impulse-bar-continuation, vol-regime-switch | G5: 30 | H5: 5 | I5: 35 | J5: 0.00086449351 | K5: 1.1999708 | L5: 0 | M5: none | N5: 0.46168216 | O5: 0.5192431 | P5: 0.77233836 | Q5: artifacts/hunt/cycle_4/report.html | R5: artifacts/hunt/cycle_4_ideas/shortlist.md | S5: 35 parameter sets have been evaluated on development data so far; the best of that many lucky trials would show a daily Sharpe near 0.0628 (annualized 1.20) with no real edge.; Walk-forward folds use fixed parameters (no per-fold re-optimization, to stay within the optimizer cap); for optimized candidates the test folds lie inside the window the parameters were tuned on, so only the locked OOS run is truly out of sample.; Max drawdown is measured on hourly bar-close equity; intrabar drawdowns are deeper.
A6: 5 | B6: 2026-10-26 20:48:21 | C6: hunt | D6: 5 hypotheses, 0 passed | E6: 5 | F6: donchian-ensemble-trend, funding-crowding-fade, noise-area-momentum, nr-compression-breakout, tsmom-vote | G6: 35 | H6: 154 | I6: 189 | J6: 0.00037351634 | K6: 1.0142773 | L6: 0 | M6: none | N6: 0.46168216 | O6: 0.5192431 | P6: 0.77233836 | Q6: artifacts/hunt/cycle_5/report.html | R6: artifacts/hunt/cycle_5_ideas/research.md | S6: 189 parameter sets have been evaluated on development data so far; the best of that many lucky trials would show a daily Sharpe near 0.0531 (annualized 1.01) with no real edge.; Walk-forward folds use fixed parameters (no per-fold re-optimization, to stay within the optimizer cap); for optimized candidates the test folds lie inside the window the parameters were tuned on, so only the locked OOS run is truly out of sample.; Max drawdown is measured on hourly bar-close equity; intrabar drawdowns are deeper.
A7: 6 | B7: 2026-10-26 20:48:22 | C7: hunt | D7: 5 hypotheses, 0 passed | E7: 5 | F7: max-min-daily, mtf-trend-pullback, efficiency-regime-switch, volume-conditioned-reversal, crowding-filtered-breakout | G7: 189 | H7: 5 | I7: 194 | J7: 0.00038629611 | K7: 1.0347019 | L7: 0 | M7: none | N7: 0.46168216 | O7: 0.5192431 | P7: 0.77233836 | Q7: artifacts/hunt/cycle_6/report.html | R7: artifacts/hunt/cycle_5_ideas/research.md | S7: 194 parameter sets have been evaluated on development data so far; the best of that many lucky trials would show a daily Sharpe near 0.0542 (annualized 1.03) with no real edge.; Walk-forward folds use fixed parameters (no per-fold re-optimization, to stay within the optimizer cap); for optimized candidates the test folds lie inside the window the parameters were tuned on, so only the locked OOS run is truly out of sample.; Max drawdown is measured on hourly bar-close equity; intrabar drawdowns are deeper.
A8: 7 | B8: 2026-10-26 20:50:57 | C8: hunt | D8: 3 hypotheses, 0 passed | E8: 3 | F8: funding-tilt, ema-cross-control, funding-carry-tilt | G8: 194 | H8: 3 | I8: 197 | J8: 0.00039894474 | K8: 1.0534237 | L8: 0 | M8: none | N8: 0.46168216 | O8: 0.5192431 | P8: 0.77233836 | Q8: artifacts/hunt/cycle_7/report.html | R8: artifacts/hunt/cycle_5_ideas/research.md | S8: 197 parameter sets have been evaluated on development data so far; the best of that many lucky trials would show a daily Sharpe near 0.0551 (annualized 1.05) with no real edge.; Walk-forward folds use fixed parameters (no per-fold re-optimization, to stay within the optimizer cap); for optimized candidates the test folds lie inside the window the parameters were tuned on, so only the locked OOS run is truly out of sample.; Max drawdown is measured on hourly bar-close equity; intrabar drawdowns are deeper.
A9: 8 | B9: 2026-10-26 20:51:54 | C9: hunt | D9: 1 hypotheses, 0 passed | E9: 1 | F9: funding-fade-wide | G9: 197 | H9: 100 | I9: 297 | J9: 0.00036189509 | K9: 1.0512041 | L9: 1 | M9: none | N9: 0.46168216 | O9: 0.5192431 | P9: 0.77233836 | Q9: artifacts/hunt/cycle_8/report.html | R9: artifacts/hunt/cycle_5_ideas/research.md | S9: 297 parameter sets have been evaluated on development data so far; the best of that many lucky trials would show a daily Sharpe near 0.0550 (annualized 1.05) with no real edge.; Walk-forward folds use fixed parameters (no per-fold re-optimization, to stay within the optimizer cap); for optimized candidates the test folds lie inside the window the parameters were tuned on, so only the locked OOS run is truly out of sample.; Max drawdown is measured on hourly bar-close equity; intrabar drawdowns are deeper.
A10: 9 | B10: 2026-10-26 21:58:25 | C10: hunt | D10: 5 hypotheses, 0 passed | E10: 5 | F10: cipher-b-dots, cipher-b-sommi-flag, cipher-b-divergence, cipher-a-ribbon, cipher-b-confluence | G10: 297 | H10: 5 | I10: 302 | J10: 0.00036432362 | K10: 1.0566401 | L10: 0 | M10: none | N10: 0.46168216 | O10: 0.5192431 | P10: 0.77233836 | Q10: artifacts/hunt/cycle_9/report.html | R10: artifacts/hunt/cycle_9_ideas/research.md | S10: 302 parameter sets have been evaluated on development data so far; the best of that many lucky trials would show a daily Sharpe near 0.0553 (annualized 1.06) with no real edge.; Walk-forward folds use fixed parameters (no per-fold re-optimization, to stay within the optimizer cap); for optimized candidates the test folds lie inside the window the parameters were tuned on, so only the locked OOS run is truly out of sample.; Max drawdown is measured on hourly bar-close equity; intrabar drawdowns are deeper.
A11: 10 | B11: 2026-10-26 21:58:25 | C11: hunt | D11: 3 hypotheses, 0 passed | E11: 3 | F11: supertrend, squeeze-momentum, ichimoku-cloud | G11: 302 | H11: 3 | I11: 305 | J11: 0.00036181844 | K11: 1.0541294 | L11: 0 | M11: none | N11: 0.46168216 | O11: 0.5192431 | P11: 0.77233836 | Q11: artifacts/hunt/cycle_10/report.html | R11: artifacts/hunt/cycle_9_ideas/research.md | S11: 305 parameter sets have been evaluated on development data so far; the best of that many lucky trials would show a daily Sharpe near 0.0552 (annualized 1.05) with no real edge.; Walk-forward folds use fixed parameters (no per-fold re-optimization, to stay within the optimizer cap); for optimized candidates the test folds lie inside the window the parameters were tuned on, so only the locked OOS run is truly out of sample.; Max drawdown is measured on hourly bar-close equity; intrabar drawdowns are deeper.
A12: 11 | B12: 2026-10-26 22:42:29 | C12: hunt | D12: 4 hypotheses, 0 passed | E12: 4 | F12: dca-grid-long, dca-grid-short, dca-rsi-long, dca-trend-long | G12: 305 | H12: 4 | I12: 309 | J12: 0.00038265686 | K12: 1.0855881 | L12: 0 | M12: none | N12: 0.46168216 | O12: 0.5192431 | P12: 0.77233836 | Q12: artifacts/hunt/cycle_11/report.html | R12: artifacts/hunt/cycle_11_ideas/research.md | S12: 309 parameter sets have been evaluated on development data so far; the best of that many lucky trials would show a daily Sharpe near 0.0568 (annualized 1.09) with no real edge.; Walk-forward folds use fixed parameters (no per-fold re-optimization, to stay within the optimizer cap); for optimized candidates the test folds lie inside the window the parameters were tuned on, so only the locked OOS run is truly out of sample.; Max drawdown is measured on hourly bar-close equity; intrabar drawdowns are deeper.
A13: 12 | B13: 2026-10-27 18:47:12 | C13: hunt | D13: 3 hypotheses, 0 passed | E13: 3 | F13: cascade-fade, turmoil-reversal, round-number-bounce | G13: 309 | H13: 3 | I13: 312 | J13: 0.00040866716 | K13: 1.1230467 | L13: 0 | M13: none | N13: 0.46168216 | O13: 0.5192431 | P13: 0.77233836 | Q13: artifacts/hunt/cycle_12/report.html | R13: artifacts/hunt/cycle_12_ideas/research.md | S13: 312 parameter sets have been evaluated on development data so far; the best of that many lucky trials would show a daily Sharpe near 0.0588 (annualized 1.12) with no real edge.; Walk-forward folds use fixed parameters (no per-fold re-optimization, to stay within the optimizer cap); for optimized candidates the test folds lie inside the window the parameters were tuned on, so only the locked OOS run is truly out of sample.; Max drawdown is measured on hourly bar-close equity; intrabar drawdowns are deeper.

Sheet Settings
A1: Section | B1: Setting | C1: Value | D1: Notes
A2: Consistency | B2: Same settings in every cycle | C2: no | D2: Cycles 3, 4, 5, 6, 7, 8, 9, 10, 11 differ from cycle 12; see each cycle's report.json.
A3: Data | B3: Symbol | C3: BTCUSDT | D3: Bybit USDT perpetual, public market data fetched locally by `fetch`.
A4: Data | B4: Bar interval (minutes) | C4: 60
A5: Windows | B5: Development from | C5: 2021-01-01 | D5: Optimization and all kill rules use this window only.
A6: Windows | B6: Development to (exclusive) | C6: 2024-01-01
A7: Windows | B7: Locked OOS from | C7: 2024-01-01 | D7: Used once per surviving candidate; every access is logged in artifacts/oos_access.log.
A8: Windows | B8: Locked OOS to (exclusive) | C8: 2026-10-26
A9: Account | B9: Initial capital $ | C9: 10000 | D9: Every run starts flat with this balance.
A10: Costs | B10: Commission per side | C10: 0.0004 | D10: Fraction of notional, charged on entry and exit.
A11: Costs | B11: Slippage per side | C11: 0.0002 | D11: Applied against the trade on every fill.
